Workbook

Sheet Dados
A1: PARÂMETROS DO PROJETO — SOLONÓPOLE/CE
A3: População de Projeto P (hab) | B3: 18851.24 | C3: ← edite aqui se necessário
A4: Consumo per capita q (L/hab.dia) | B4: 150 | C4: ← edite aqui se necessário
A5: Coef. dia maior consumo K1 | B5: 1.2 | C5: ← edite aqui se necessário
A6: Coef. hora maior consumo K2 | B6: 1.5 | C6: ← edite aqui se necessário
A7: Área Total do Projeto (m²) | B7: 1035079.2 | C7: ← edite aqui se necessário
A8: Comprimento Total da Rede (m) | B8: 20397.79 | C8: ← edite aqui se necessário
A9: Vazão Média Qm (L/s) | B9: =(B4*B3)/86400 -> 32.727847 | C9: ← edite aqui se necessário
A10: Vazão Máx. Diária Qmd (L/s) | B10: =B9*B5 -> 39.273417 | C10: ← edite aqui se necessário
A11: Vazão Máx. Horária Qmh (L/s) | B11: =B10*B6 -> 58.910125 | C11: ← edite aqui se necessário

Sheet Projeção Populacional
A1: PROJEÇÃO POPULACIONAL — MÉTODO TAXA DECRESCENTE DE CRESCIMENTO
A3: Ano | B3: Pop. Total (hab) | C3: Qm (L/s) | D3: Qmd = K1·Qm (L/s) | E3: Qmh = K1·K2·Qm (L/s)
A4: 2022 | B4: 18265 | C4: 36.427 | D4: 43.7125 | E4: 65.5687
A5: 2023 | B5: 18303 | C5: 36.3147 | D5: 43.5776 | E5: 65.3664
A6: 2024 | B6: 18339 | C6: 36.3866 | D6: 43.6639 | E6: 65.4959
A7: 2025 | B7: 18374 | C7: 36.4556 | D7: 43.7467 | E7: 65.6201
A8: 2026 | B8: 18407 | C8: 36.5218 | D8: 43.8262 | E8: 65.7393
A9: 2027 | B9: 18439 | C9: 36.5853 | D9: 43.9024 | E9: 65.8536
A10: 2028 | B10: 18470 | C10: 36.6463 | D10: 43.9755 | E10: 65.9633
A11: 2029 | B11: 18499 | C11: 40.7112 | D11: 48.8535 | E11: 73.2802
A12: 2030 | B12: 18527 | C12: 41.6795 | D12: 50.0154 | E12: 75.0232
A13: 2031 | B13: 18555 | C13: 42.6479 | D13: 51.1775 | E13: 76.7663
A14: 2032 | B14: 18581 | C14: 43.0106 | D14: 51.6128 | E14: 77.4191
A15: 2033 | B15: 18606 | C15: 43.9657 | D15: 52.7588 | E15: 79.1382
... A28: 2046 | B28: 18851 | C28: 43.6371 | D28: 52.3646 | E28: 78.5469

Sheet Método Área Nodal
A1: MÉTODO DA ÁREA NODAL
A3: Obs: Pop. do Nó e Vazão calculadas por fórmulas referenciando aba 'Dados'
A5: Nó | B5: Área Nodal (m²) | C5: Área Nodal (ha) | D5: % Área Total | E5: Pop. do Nó (hab) | F5: Vazão Nodal Qmh (L/s) | G5: Obs.
A6: N1 | B6: 9716.98 | C6: =B6/10000 -> 0.971698 | D6: =B6/Dados!$B$7*100 -> 0.9387668 | E6: =Dados!$B$3*(B6/Dados!$B$7) -> 176.96918 | F6: =E6*Dados!$B$4*Dados!$B$5*Dados!$B$6/86400 -> 0.5530287
A7: N2 | B7: 5781.42 | C7: =B7/10000 -> 0.578142 | D7: =B7/Dados!$B$7*100 -> 0.55854856 | E7: =Dados!$B$3*(B7/Dados!$B$7) -> 105.29333 | F7: =E7*Dados!$B$4*Dados!$B$5*Dados!$B$6/86400 -> 0.32904165
A8: N3 | B8: 4732.11 | C8: =B8/10000 -> 0.473211 | D8: =B8/Dados!$B$7*100 -> 0.45717371 | E8: =Dados!$B$3*(B8/Dados!$B$7) -> 86.182913 | F8: =E8*Dados!$B$4*Dados!$B$5*Dados!$B$6/86400 -> 0.2693216
A9: N4 | B9: 6907.88 | C9: =B9/10000 -> 0.690788 | D9: =B9/Dados!$B$7*100 -> 0.66737694 | E9: =Dados!$B$3*(B9/Dados!$B$7) -> 125.80883 | F9: =E9*Dados!$B$4*Dados!$B$5*Dados!$B$6/86400 -> 0.39315259
A10: N5 | B10: 8584.93 | C10: =B10/10000 -> 0.858493 | D10: =B10/Dados!$B$7*100 -> 0.82939836 | E10: =Dados!$B$3*(B10/Dados!$B$7) -> 156.35188 | F10: =E10*Dados!$B$4*Dados!$B$5*Dados!$B$6/86400 -> 0.48859961
A11: N6 | B11: 2742.1 | C11: =B11/10000 -> 0.27421 | D11: =B11/Dados!$B$7*100 -> 0.26491692 | E11: =Dados!$B$3*(B11/Dados!$B$7) -> 49.940125 | F11: =E11*Dados!$B$4*Dados!$B$5*Dados!$B$6/86400 -> 0.15606289
A12: N7 | B12: 3132.1 | C12: =B12/10000 -> 0.31321 | D12: =B12/Dados!$B$7*100 -> 0.3025952 | E12: =Dados!$B$3*(B12/Dados!$B$7) -> 57.042947 | F12: =E12*Dados!$B$4*Dados!$B$5*Dados!$B$6/86400 -> 0.17825921
A13: N8 | B13: 6896.41 | C13: =B13/10000 -> 0.689641 | D13: =B13/Dados!$B$7*100 -> 0.66626882 | E13: =Dados!$B$3*(B13/Dados!$B$7) -> 125.59993 | F13: =E13*Dados!$B$4*Dados!$B$5*Dados!$B$6/86400 -> 0.39249979
A14: N9 | B14: 7926.07 | C14: =B14/10000 -> 0.792607 | D14: =B14/Dados!$B$7*100 -> 0.76574526 | E14: =Dados!$B$3*(B14/Dados!$B$7) -> 144.35248 | F14: =E14*Dados!$B$4*Dados!$B$5*Dados!$B$6/86400 -> 0.45110149
A15: N10 | B15: 10871.71 | C15: =B15/10000 -> 1.087171 | D15: =B15/Dados!$B$7*100 -> 1.0503264 | E15: =Dados!$B$3*(B15/Dados!$B$7) -> 197.99955 | F15: =E15*Dados!$B$4*Dados!$B$5*Dados!$B$6/86400 -> 0.61874858
A16: N11 | B16: 12057.04 | C16: =B16/10000 -> 1.205704 | D16: =B16/Dados!$B$7*100 -> 1.1648423 | E16: =Dados!$B$3*(B16/Dados!$B$7) -> 219.58721 | F16: =E16*Dados!$B$4*Dados!$B$5*Dados!$B$6/86400 -> 0.68621003
A17: N12 | B17: 9832.89 | C17: =B17/10000 -> 0.983289 | D17: =B17/Dados!$B$7*100 -> 0.94996498 | E17: =Dados!$B$3*(B17/Dados!$B$7) -> 179.08018 | F17: =E17*Dados!$B$4*Dados!$B$5*Dados!$B$6/86400 -> 0.55962556
... A172: N170 | B172: 3235.64 | C172: =B172/10000 -> 0.323564 | D172: =B172/Dados!$B$7*100 -> 0.3125983 | E172: =Dados!$B$3*(B172/Dados!$B$7) -> 58.928656 | F172: =E172*Dados!$B$4*Dados!$B$5*Dados!$B$6/86400 -> 0.18415205
A173: N171 | B173: 9811.65 | C173: =B173/10000 -> 0.981165 | D173: =B173/Dados!$B$7*100 -> 0.94791296 | E173: =Dados!$B$3*(B173/Dados!$B$7) -> 178.69335 | F173: =E173*Dados!$B$4*Dados!$B$5*Dados!$B$6/86400 -> 0.55841671 | G173: 2 polígonos somados
A174: N172 | B174: 5046.74 | C174: =B174/10000 -> 0.504674 | D174: =B174/Dados!$B$7*100 -> 0.48757042 | E174: =Dados!$B$3*(B174/Dados!$B$7) -> 91.913069 | F174: =E174*Dados!$B$4*Dados!$B$5*Dados!$B$6/86400 -> 0.28722834
A175: N173 | B175: 2885.21 | C175: =B175/10000 -> 0.288521 | D175: =B175/Dados!$B$7*100 -> 0.27874292 | E175: =Dados!$B$3*(B175/Dados!$B$7) -> 52.546497 | F175: =E175*Dados!$B$4*Dados!$B$5*Dados!$B$6/86400 -> 0.1642078
A176: N174 | B176: 7992.37 | C176: =B176/10000 -> 0.799237 | D176: =B176/Dados!$B$7*100 -> 0.77215057 | E176: =Dados!$B$3*(B176/Dados!$B$7) -> 145.55996 | F176: =E176*Dados!$B$4*Dados!$B$5*Dados!$B$6/86400 -> 0.45487486
A177: N175 | B177: 11697.16 | C177: =B177/10000 -> 1.169716 | D177: =B177/Dados!$B$7*100 -> 1.1300739 | E177: =Dados!$B$3*(B177/Dados!$B$7) -> 213.03294 | F177: =E177*Dados!$B$4*Dados!$B$5*Dados!$B$6/86400 -> 0.66572795
A178: N176 | B178: 6344.61 | C178: =B178/10000 -> 0.634461 | D178: =B178/Dados!$B$7*100 -> 0.61295889 | E178: =Dados!$B$3*(B178/Dados!$B$7) -> 115.55035 | F178: =E178*Dados!$B$4*Dados!$B$5*Dados!$B$6/86400 -> 0.36109485
A179: N177 | B179: 2646.74 | C179: =B179/10000 -> 0.264674 | D179: =B179/Dados!$B$7*100 -> 0.2557041 | E179: =Dados!$B$3*(B179/Dados!$B$7) -> 48.203394 | F179: =E179*Dados!$B$4*Dados!$B$5*Dados!$B$6/86400 -> 0.15063561
A180: N178 | B180: 5500.14 | C180: =B180/10000 -> 0.550014 | D180: =B180/Dados!$B$7*100 -> 0.53137383 | E180: =Dados!$B$3*(B180/Dados!$B$7) -> 100.17056 | F180: =E180*Dados!$B$4*Dados!$B$5*Dados!$B$6/86400 -> 0.31303299
A181: N179 | B181: 8700.3 | C181: =B181/10000 -> 0.87003 | D181: =B181/Dados!$B$7*100 -> 0.84054437 | E181: =Dados!$B$3*(B181/Dados!$B$7) -> 158.45304 | F181: =E181*Dados!$B$4*Dados!$B$5*Dados!$B$6/86400 -> 0.49516574
A182: N180 | B182: 2042.12 | C182: =B182/10000 -> 0.204212 | D182: =B182/Dados!$B$7*100 -> 0.19729118 | E182: =Dados!$B$3*(B182/Dados!$B$7) -> 37.191834 | F182: =E182*Dados!$B$4*Dados!$B$5*Dados!$B$6/86400 -> 0.11622448
A183: N181 | B183: 5911.12 | C183: =B183/10000 -> 0.591112 | D183: =B183/Dados!$B$7*100 -> 0.571079 | E183: =Dados!$B$3*(B183/Dados!$B$7) -> 107.65547 | F183: =E183*Dados!$B$4*Dados!$B$5*Dados!$B$6/86400 -> 0.33642335
A184: N182 | B184: 2506.26 | C184: =B184/10000 -> 0.250626 | D184: =B184/Dados!$B$7*100 -> 0.24213219 | E184: =Dados!$B$3*(B184/Dados!$B$7) -> 45.644921 | F184: =E184*Dados!$B$4*Dados!$B$5*Dados!$B$6/86400 -> 0.14264038
A185: N183 | B185: 1227.35 | C185: =B185/10000 -> 0.122735 | D185: =B185/Dados!$B$7*100 -> 0.11857547 | E185: =Dados!$B$3*(B185/Dados!$B$7) -> 22.352946 | F185: =E185*Dados!$B$4*Dados!$B$5*Dados!$B$6/86400 -> 0.069852955
A186: TOTAL | B186: 1035079.2 | C186: =B186/10000 -> 103.50792 | D186: 100% | E186: =SUM(E6:E185) -> 18851.241 | F186: =SUM(F6:F185) -> 58.910128

Sheet Método Linear
A1: MÉTODO LINEAR DO NÓ
A3: Obs: Pop. do Nó e Vazão calculadas por fórmulas referenciando aba 'Dados'
A5: Nó | B5: Trechos Adjacentes | C5: Comp. Nodal (m) | D5: % Comp. Total | E5: Pop. do Nó (hab) | F5: Vazão Nodal Qmh (L/s)
A6: N1 | B6: T200, T201, T8, T9 | C6: 152.91 | D6: =C6/Dados!$B$8*100 -> 0.74964003 | E6: =Dados!$B$3*(C6/Dados!$B$8) -> 141.31644 | F6: =E6*Dados!$B$4*Dados!$B$5*Dados!$B$6/86400 -> 0.44161388
A7: N2 | B7: T1, T201, T37, T40 | C7: 148.46 | D7: =C7/Dados!$B$8*100 -> 0.72782395 | E7: =Dados!$B$3*(C7/Dados!$B$8) -> 137.20384 | F7: =E7*Dados!$B$4*Dados!$B$5*Dados!$B$6/86400 -> 0.428762
A8: N3 | B8: T1, T209, T210, T44 | C8: 226.43 | D8: =C8/Dados!$B$8*100 -> 1.1100712 | E8: =Dados!$B$3*(C8/Dados!$B$8) -> 209.26219 | F8: =E8*Dados!$B$4*Dados!$B$5*Dados!$B$6/86400 -> 0.65394435
A9: N4 | B9: T168, T44, T45, T74 | C9: 168.38 | D9: =C9/Dados!$B$8*100 -> 0.82548158 | E9: =Dados!$B$3*(C9/Dados!$B$8) -> 155.61351 | F9: =E9*Dados!$B$4*Dados!$B$5*Dados!$B$6/86400 -> 0.48629223
A10: N5 | B10: T169, T170, T45, T46 | C10: 190.49 | D10: =C10/Dados!$B$8*100 -> 0.93387568 | E10: =Dados!$B$3*(C10/Dados!$B$8) -> 176.04715 | F10: =E10*Dados!$B$4*Dados!$B$5*Dados!$B$6/86400 -> 0.55014733
A11: N6 | B11: T170, T198, T2 | C11: 70.62 | D11: =C11/Dados!$B$8*100 -> 0.34621398 | E11: =Dados!$B$3*(C11/Dados!$B$8) -> 65.265628 | F11: =E11*Dados!$B$4*Dados!$B$5*Dados!$B$6/86400 -> 0.20395509
A12: N7 | B12: T198, T209, T8 | C12: 92.09 | D12: =C12/Dados!$B$8*100 -> 0.45147048 | E12: =Dados!$B$3*(C12/Dados!$B$8) -> 85.107783 | F12: =E12*Dados!$B$4*Dados!$B$5*Dados!$B$6/86400 -> 0.26596182
A13: N8 | B13: T2, T3, T6 | C13: 158.98 | D13: =C13/Dados!$B$8*100 -> 0.77939816 | E13: =Dados!$B$3*(C13/Dados!$B$8) -> 146.92622 | F13: =E13*Dados!$B$4*Dados!$B$5*Dados!$B$6/86400 -> 0.45914443
A14: N9 | B14: T5, T6, T7 | C14: 141 | D14: =C14/Dados!$B$8*100 -> 0.69125136 | E14: =Dados!$B$3*(C14/Dados!$B$8) -> 130.30945 | F14: =E14*Dados!$B$4*Dados!$B$5*Dados!$B$6/86400 -> 0.40721704
A15: N10 | B15: T17, T4, T5 | C15: 170.21 | D15: =C15/Dados!$B$8*100 -> 0.83445314 | E15: =Dados!$B$3*(C15/Dados!$B$8) -> 157.30476 | F15: =E15*Dados!$B$4*Dados!$B$5*Dados!$B$6/86400 -> 0.49157739
A16: N11 | B16: T16, T17, T19, T20 | C16: 256.67 | D16: =C16/Dados!$B$8*100 -> 1.2583226 | E16: =Dados!$B$3*(C16/Dados!$B$8) -> 237.20941 | F16: =E16*Dados!$B$4*Dados!$B$5*Dados!$B$6/86400 -> 0.74127941
A17: N12 | B17: T20, T21, T234, T28 | C17: 223.14 | D17: =C17/Dados!$B$8*100 -> 1.093942 | E17: =Dados!$B$3*(C17/Dados!$B$8) -> 206.22164 | F17: =E17*Dados!$B$4*Dados!$B$5*Dados!$B$6/86400 -> 0.64444262
... A188: N183 | B188: T222, T248 | C188: 33.84 | D188: =C188/Dados!$B$8*100 -> 0.16590033 | E188: =Dados!$B$3*(C188/Dados!$B$8) -> 31.274269 | F188: =E188*Dados!$B$4*Dados!$B$5*Dados!$B$6/86400 -> 0.097732089
A189: TOTAL | C189: 20397.79 | D189: =SUM(D6:D188) -> 99.613684 | E189: =SUM(E6:E188) -> 18778.415 | F189: =SUM(F6:F188) -> 58.682546

Sheet Trechos
A1: TRECHOS DA REDE
A3: Trecho | B3: Nó Inicial | C3: Nó Final | D3: Comprimento (m) | E3: L/2 (m)
A4: T1 | B4: N2 | C4: N3 | D4: 42.41 | E4: =D4/2 -> 21.205
A5: T2 | B5: N6 | C5: N8 | D5: 65.46 | E5: =D5/2 -> 32.73
A6: T3 | B6: N8 | C6: N39 | D6: 54.18 | E6: =D6/2 -> 27.09
A7: T4 | B7: N39 | C7: N10 | D7: 221.82 | E7: =D7/2 -> 110.91
A8: T5 | B8: N10 | C8: N9 | D8: 52.91 | E8: =D8/2 -> 26.455
A9: T6 | B9: N9 | C9: N8 | D9: 198.32 | E9: =D9/2 -> 99.16
A10: T7 | B10: N9 | C10: N164 | D10: 30.76 | E10: =D10/2 -> 15.38
A11: T8 | B11: N1 | C11: N7 | D11: 72.88 | E11: =D11/2 -> 36.44
A12: T9 | B12: N1 | C12: N25 | D12: 139.57 | E12: =D12/2 -> 69.785
A13: T10 | B13: N25 | C13: N169 | D13: 35.86 | E13: =D13/2 -> 17.93
A14: T11 | B14: N25 | C14: N23 | D14: 165.52 | E14: =D14/2 -> 82.76
A15: T12 | B15: N22 | C15: N21 | D15: 6.77 | E15: =D15/2 -> 3.385
... A254: T251 | B254: N47 | C254: N48 | D254: 104.27 | E254: =D254/2 -> 52.135
A255: TOTAL | D255: =SUM(D2:D254) -> 20397.79 | E255: =SUM(E2:E254) -> 10198.895

Sheet Comparação
A1: COMPARAÇÃO DOS MÉTODOS — ÁREA NODAL × LINEAR
A3: ⚠️ Diferenças por nó são ESPERADAS e NORMAIS entre os dois métodos. | B3: O que deve concordar é a VAZÃO TOTAL (última linha).
A5: Nó | B5: Qmh Área Nodal (L/s) | C5: Qmh Método Linear (L/s) | D5: Diferença (L/s) | E5: Diferença (%) | F5: Análise
A6: N1 | B6: ='Método Área Nodal'!F6 -> 0.5530287 | C6: ='Método Linear'!F6 -> 0.44161388 | D6: =B6-C6 -> 0.11141482 | E6: =IF(B6=0,"-",ABS(D6/B6)*100) -> 20.146299 | F6: =IF(B6=0,"sem área",IF(ABS(D6/B6)*100<20,"✅ OK",IF(ABS(D6/B6)*100<50,"⚠️ Moderado","❌ Divergente"))) -> ⚠️ Moderado
A7: N2 | B7: ='Método Área Nodal'!F7 -> 0.32904165 | C7: ='Método Linear'!F7 -> 0.428762 | D7: =B7-C7 -> -0.099720343 | E7: =IF(B7=0,"-",ABS(D7/B7)*100) -> 30.306298 | F7: =IF(B7=0,"sem área",IF(ABS(D7/B7)*100<20,"✅ OK",IF(ABS(D7/B7)*100<50,"⚠️ Moderado","❌ Divergente"))) -> ⚠️ Moderado
A8: N3 | B8: ='Método Área Nodal'!F8 -> 0.2693216 | C8: ='Método Linear'!F8 -> 0.65394435 | D8: =B8-C8 -> -0.38462275 | E8: =IF(B8=0,"-",ABS(D8/B8)*100) -> 142.8117 | F8: =IF(B8=0,"sem área",IF(ABS(D8/B8)*100<20,"✅ OK",IF(ABS(D8/B8)*100<50,"⚠️ Moderado","❌ Divergente"))) -> ❌ Divergente
A9: N4 | B9: ='Método Área Nodal'!F9 -> 0.39315259 | C9: ='Método Linear'!F9 -> 0.48629223 | D9: =B9-C9 -> -0.093139641 | E9: =IF(B9=0,"-",ABS(D9/B9)*100) -> 23.690456 | F9: =IF(B9=0,"sem área",IF(ABS(D9/B9)*100<20,"✅ OK",IF(ABS(D9/B9)*100<50,"⚠️ Moderado","❌ Divergente"))) -> ⚠️ Moderado
A10: N5 | B10: ='Método Área Nodal'!F10 -> 0.48859961 | C10: ='Método Linear'!F10 -> 0.55014733 | D10: =B10-C10 -> -0.061547719 | E10: =IF(B10=0,"-",ABS(D10/B10)*100) -> 12.59676 | F10: =IF(B10=0,"sem área",IF(ABS(D10/B10)*100<20,"✅ OK",IF(ABS(D10/B10)*100<50,"⚠️ Moderado","❌ Divergente"))) -> ✅ OK
A11: N6 | B11: ='Método Área Nodal'!F11 -> 0.15606289 | C11: ='Método Linear'!F11 -> 0.20395509 | D11: =B11-C11 -> -0.047892196 | E11: =IF(B11=0,"-",ABS(D11/B11)*100) -> 30.687754 | F11: =IF(B11=0,"sem área",IF(ABS(D11/B11)*100<20,"✅ OK",IF(ABS(D11/B11)*100<50,"⚠️ Moderado","❌ Divergente"))) -> ⚠️ Moderado
A12: N7 | B12: ='Método Área Nodal'!F12 -> 0.17825921 | C12: ='Método Linear'!F12 -> 0.26596182 | D12: =B12-C12 -> -0.087702613 | E12: =IF(B12=0,"-",ABS(D12/B12)*100) -> 49.199485 | F12: =IF(B12=0,"sem área",IF(ABS(D12/B12)*100<20,"✅ OK",IF(ABS(D12/B12)*100<50,"⚠️ Moderado","❌ Divergente"))) -> ⚠️ Moderado
A13: N8 | B13: ='Método Área Nodal'!F13 -> 0.39249979 | C13: ='Método Linear'!F13 -> 0.45914443 | D13: =B13-C13 -> -0.066644638 | E13: =IF(B13=0,"-",ABS(D13/B13)*100) -> 16.979535 | F13: =IF(B13=0,"sem área",IF(ABS(D13/B13)*100<20,"✅ OK",IF(ABS(D13/B13)*100<50,"⚠️ Moderado","❌ Divergente"))) -> ✅ OK
A14: N9 | B14: ='Método Área Nodal'!F14 -> 0.45110149 | C14: ='Método Linear'!F14 -> 0.40721704 | D14: =B14-C14 -> 0.043884453 | E14: =IF(B14=0,"-",ABS(D14/B14)*100) -> 9.7282881 | F14: =IF(B14=0,"sem área",IF(ABS(D14/B14)*100<20,"✅ OK",IF(ABS(D14/B14)*100<50,"⚠️ Moderado","❌ Divergente"))) -> ✅ OK
A15: N10 | B15: ='Método Área Nodal'!F15 -> 0.61874858 | C15: ='Método Linear'!F15 -> 0.49157739 | D15: =B15-C15 -> 0.12717119 | E15: =IF(B15=0,"-",ABS(D15/B15)*100) -> 20.552967 | F15: =IF(B15=0,"sem área",IF(ABS(D15/B15)*100<20,"✅ OK",IF(ABS(D15/B15)*100<50,"⚠️ Moderado","❌ Divergente"))) -> ⚠️ Moderado
A16: N11 | B16: ='Método Área Nodal'!F16 -> 0.68621003 | C16: ='Método Linear'!F16 -> 0.74127941 | D16: =B16-C16 -> -0.055069384 | E16: =IF(B16=0,"-",ABS(D16/B16)*100) -> 8.0251501 | F16: =IF(B16=0,"sem área",IF(ABS(D16/B16)*100<20,"✅ OK",IF(ABS(D16/B16)*100<50,"⚠️ Moderado","❌ Divergente"))) -> ✅ OK
A17: N12 | B17: ='Método Área Nodal'!F17 -> 0.55962556 | C17: ='Método Linear'!F17 -> 0.64444262 | D17: =B17-C17 -> -0.084817066 | E17: =IF(B17=0,"-",ABS(D17/B17)*100) -> 15.156039 | F17: =IF(B17=0,"sem área",IF(ABS(D17/B17)*100<20,"✅ OK",IF(ABS(D17/B17)*100<50,"⚠️ Moderado","❌ Divergente"))) -> ✅ OK
... A21: N16 | B21: ='Método Área Nodal'!F21 -> 0.45121703 | C21: ='Método Linear'!F21 -> 0.2983659 | D21: =B21-C21 -> 0.15285112 | E21: =IF(B21=0,"-",ABS(D21/B21)*100) -> 33.8753 | F21: =IF(B21=0,"sem área",IF(ABS(D21/B21)*100<20,"✅ OK",IF(ABS(D21/B21)*100<50,"⚠️ Moderado","❌ Divergente"))) -> ⚠️ Moderado
A22: N18 | B22: ='Método Área Nodal'!F22 -> 0.63474644 | C22: ='Método Linear'!F23 -> 0.60793749 | D22: =B22-C22 -> 0.026808946 | E22: =IF(B22=0,"-",ABS(D22/B22)*100) -> 4.2235677 | F22: =IF(B22=0,"sem área",IF(ABS(D22/B22)*100<20,"✅ OK",IF(ABS(D22/B22)*100<50,"⚠️ Moderado","❌ Divergente"))) -> ✅ OK
A23: N19 | B23: ='Método Área Nodal'!F23 -> 0.41813654 | C23: ='Método Linear'!F24 -> 0.42778005 | D23: =B23-C23 -> -0.0096435129 | E23: =IF(B23=0,"-",ABS(D23/B23)*100) -> 2.3063071 | F23: =IF(B23=0,"sem área",IF(ABS(D23/B23)*100<20,"✅ OK",IF(ABS(D23/B23)*100<50,"⚠️ Moderado","❌ Divergente"))) -> ✅ OK
A24: N20 | B24: ='Método Área Nodal'!F24 -> 0.47039351 | C24: ='Método Linear'!F25 -> 0.42474759 | D24: =B24-C24 -> 0.04564592 | E24: =IF(B24=0,"-",ABS(D24/B24)*100) -> 9.7037734 | F24: =IF(B24=0,"sem área",IF(ABS(D24/B24)*100<20,"✅ OK",IF(ABS(D24/B24)*100<50,"⚠️ Moderado","❌ Divergente"))) -> ✅ OK
A25: N22 | B25: ='Método Área Nodal'!F25 -> 0.84739287 | C25: ='Método Linear'!F27 -> 0.52998864 | D25: =B25-C25 -> 0.31740423 | E25: =IF(B25=0,"-",ABS(D25/B25)*100) -> 37.456561 | F25: =IF(B25=0,"sem área",IF(ABS(D25/B25)*100<20,"✅ OK",IF(ABS(D25/B25)*100<50,"⚠️ Moderado","❌ Divergente"))) -> ⚠️ Moderado
A26: N23 | B26: ='Método Área Nodal'!F26 -> 0.49851681 | C26: ='Método Linear'!F28 -> 0.53076842 | D26: =B26-C26 -> -0.032251607 | E26: =IF(B26=0,"-",ABS(D26/B26)*100) -> 6.4695125 | F26: =IF(B26=0,"sem área",IF(ABS(D26/B26)*100<20,"✅ OK",IF(ABS(D26/B26)*100<50,"⚠️ Moderado","❌ Divergente"))) -> ✅ OK
A27: N24 | B27: ='Método Área Nodal'!F27 -> 0.26913493 | C27: ='Método Linear'!F29 -> 0.23208483 | D27: =B27-C27 -> 0.037050095 | E27: =IF(B27=0,"-",ABS(D27/B27)*100) -> 13.766364 | F27: =IF(B27=0,"sem área",IF(ABS(D27/B27)*100<20,"✅ OK",IF(ABS(D27/B27)*100<50,"⚠️ Moderado","❌ Divergente"))) -> ✅ OK
A28: N25 | B28: ='Método Área Nodal'!F28 -> 0.44540102 | C28: ='Método Linear'!F30 -> 0.49232829 | D28: =B28-C28 -> -0.046927267 | E28: =IF(B28=0,"-",ABS(D28/B28)*100) -> 10.535958 | F28: =IF(B28=0,"sem área",IF(ABS(D28/B28)*100<20,"✅ OK",IF(ABS(D28/B28)*100<50,"⚠️ Moderado","❌ Divergente"))) -> ✅ OK
A29: N26 | B29: ='Método Área Nodal'!F29 -> 0.16031491 | C29: ='Método Linear'!F31 -> 0.39733986 | D29: =B29-C29 -> -0.23702495 | E29: =IF(B29=0,"-",ABS(D29/B29)*100) -> 147.8496 | F29: =IF(B29=0,"sem área",IF(ABS(D29/B29)*100<20,"✅ OK",IF(ABS(D29/B29)*100<50,"⚠️ Moderado","❌ Divergente"))) -> ❌ Divergente
A30: N27 | B30: ='Método Área Nodal'!F30 -> 0.26975415 | C30: ='Método Linear'!F32 -> 0.37137616 | D30: =B30-C30 -> -0.10162202 | E30: =IF(B30=0,"-",ABS(D30/B30)*100) -> 37.672087 | F30: =IF(B30=0,"sem área",IF(ABS(D30/B30)*100<20,"✅ OK",IF(ABS(D30/B30)*100<50,"⚠️ Moderado","❌ Divergente"))) -> ⚠️ Moderado
A31: N28 | B31: ='Método Área Nodal'!F31 -> 0.1761204 | C31: ='Método Linear'!F33 -> 0.25175255 | D31: =B31-C31 -> -0.075632152 | E31: =IF(B31=0,"-",ABS(D31/B31)*100) -> 42.943437 | F31: =IF(B31=0,"sem área",IF(ABS(D31/B31)*100<20,"✅ OK",IF(ABS(D31/B31)*100<50,"⚠️ Moderado","❌ Divergente"))) -> ⚠️ Moderado
A32: N29 | B32: ='Método Área Nodal'!F32 -> 0.10442571 | C32: ='Método Linear'!F34 -> 0.23188267 | D32: =B32-C32 -> -0.12745695 | E32: =IF(B32=0,"-",ABS(D32/B32)*100) -> 122.05514 | F32: =IF(B32=0,"sem área",IF(ABS(D32/B32)*100<20,"✅ OK",IF(ABS(D32/B32)*100<50,"⚠️ Moderado","❌ Divergente"))) -> ❌ Divergente
A33: N30 | B33: ='Método Área Nodal'!F33 -> 0.25161577 | C33: ='Método Linear'!F35 -> 0.39881277 | D33: =B33-C33 -> -0.147197 | E33: =IF(B33=0,"-",ABS(D33/B33)*100) -> 58.500706 | F33: =IF(B33=0,"sem área",IF(ABS(D33/B33)*100<20,"✅ OK",IF(ABS(D33/B33)*100<50,"⚠️ Moderado","❌ Divergente"))) -> ❌ Divergente
A34: N31 | B34: ='Método Área Nodal'!F34 -> 0.4164445 | C34: ='Método Linear'!F36 -> 0.44536836 | D34: =B34-C34 -> -0.028923866 | E34: =IF(B34=0,"-",ABS(D34/B34)*100) -> 6.9454311 | F34: =IF(B34=0,"sem área",IF(ABS(D34/B34)*100<20,"✅ OK",IF(ABS(D34/B34)*100<50,"⚠️ Moderado","❌ Divergente"))) -> ✅ OK
A35: N32 | B35: ='Método Área Nodal'!F35 -> 0.30713616 | C35: ='Método Linear'!F37 -> 0.37452415 | D35: =B35-C35 -> -0.067387989 | E35: =IF(B35=0,"-",ABS(D35/B35)*100) -> 21.940754 | F35: =IF(B35=0,"sem área",IF(ABS(D35/B35)*100<20,"✅ OK",IF(ABS(D35/B35)*100<50,"⚠️ Moderado","❌ Divergente"))) -> ⚠️ Moderado
A36: N33 | B36: ='Método Área Nodal'!F36 -> 0.17065726 | C36: ='Método Linear'!F38 -> 0.37928946 | D36: =B36-C36 -> -0.2086322 | E36: =IF(B36=0,"-",ABS(D36/B36)*100) -> 122.25217 | F36: =IF(B36=0,"sem área",IF(ABS(D36/B36)*100<20,"✅ OK",IF(ABS(D36/B36)*100<50,"⚠️ Moderado","❌ Divergente"))) -> ❌ Divergente
... A64: N61 | B64: ='Método Área Nodal'!F64 -> 0.32305775 | C64: ='Método Linear'!F66 -> 0.2524168 | D64: =B64-C64 -> 0.070640951 | E64: =IF(B64=0,"-",ABS(D64/B64)*100) -> 21.866354 | F64: =IF(B64=0,"sem área",IF(ABS(D64/B64)*100<20,"✅ OK",IF(ABS(D64/B64)*100<50,"⚠️ Moderado","❌ Divergente"))) -> ⚠️ Moderado
A65: N63 | B65: ='Método Área Nodal'!F65 -> 0.28071913 | C65: ='Método Linear'!F68 -> 0.44170052 | D65: =B65-C65 -> -0.1609814 | E65: =IF(B65=0,"-",ABS(D65/B65)*100) -> 57.346073 | F65: =IF(B65=0,"sem área",IF(ABS(D65/B65)*100<20,"✅ OK",IF(ABS(D65/B65)*100<50,"⚠️ Moderado","❌ Divergente"))) -> ❌ Divergente
A66: N64 | B66: ='Método Área Nodal'!F66 -> 0.20730964 | C66: ='Método Linear'!F69 -> 0.22480691 | D66: =B66-C66 -> -0.01749727 | E66: =IF(B66=0,"-",ABS(D66/B66)*100) -> 8.4401624 | F66: =IF(B66=0,"sem área",IF(ABS(D66/B66)*100<20,"✅ OK",IF(ABS(D66/B66)*100<50,"⚠️ Moderado","❌ Divergente"))) -> ✅ OK
A67: N65 | B67: ='Método Área Nodal'!F67 -> 0.16636597 | C67: ='Método Linear'!F70 -> 0.13588342 | D67: =B67-C67 -> 0.030482551 | E67: =IF(B67=0,"-",ABS(D67/B67)*100) -> 18.322588 | F67: =IF(B67=0,"sem área",IF(ABS(D67/B67)*100<20,"✅ OK",IF(ABS(D67/B67)*100<50,"⚠️ Moderado","❌ Divergente"))) -> ✅ OK
A68: N66 | B68: ='Método Área Nodal'!F68 -> 0.42677262 | C68: ='Método Linear'!F71 -> 0.36095025 | D68: =B68-C68 -> 0.065822366 | E68: =IF(B68=0,"-",ABS(D68/B68)*100) -> 15.423287 | F68: =IF(B68=0,"sem área",IF(ABS(D68/B68)*100<20,"✅ OK",IF(ABS(D68/B68)*100<50,"⚠️ Moderado","❌ Divergente"))) -> ✅ OK
A69: N67 | B69: ='Método Área Nodal'!F69 -> 0.34512943 | C69: ='Método Linear'!F72 -> 0.52548326 | D69: =B69-C69 -> -0.18035383 | E69: =IF(B69=0,"-",ABS(D69/B69)*100) -> 52.256868 | F69: =IF(B69=0,"sem área",IF(ABS(D69/B69)*100<20,"✅ OK",IF(ABS(D69/B69)*100<50,"⚠️ Moderado","❌ Divergente"))) -> ❌ Divergente
A70: N68 | B70: ='Método Área Nodal'!F70 -> 0.55920155 | C70: ='Método Linear'!F73 -> 0.52935327 | D70: =B70-C70 -> 0.029848281 | E70: =IF(B70=0,"-",ABS(D70/B70)*100) -> 5.3376607 | F70: =IF(B70=0,"sem área",IF(ABS(D70/B70)*100<20,"✅ OK",IF(ABS(D70/B70)*100<50,"⚠️ Moderado","❌ Divergente"))) -> ✅ OK
A71: N69 | B71: ='Método Área Nodal'!F71 -> 0.49381802 | C71: ='Método Linear'!F74 -> 0.42503639 | D71: =B71-C71 -> 0.068781629 | E71: =IF(B71=0,"-",ABS(D71/B71)*100) -> 13.928538 | F71: =IF(B71=0,"sem área",IF(ABS(D71/B71)*100<20,"✅ OK",IF(ABS(D71/B71)*100<50,"⚠️ Moderado","❌ Divergente"))) -> ✅ OK
A72: N70 | B72: ='Método Área Nodal'!F72 -> 0.31374327 | C72: ='Método Linear'!F75 -> 0.27563684 | D72: =B72-C72 -> 0.03810643 | E72: =IF(B72=0,"-",ABS(D72/B72)*100) -> 12.145736 | F72: =IF(B72=0,"sem área",IF(ABS(D72/B72)*100<20,"✅ OK",IF(ABS(D72/B72)*100<50,"⚠️ Moderado","❌ Divergente"))) -> ✅ OK
...
